<?xml version="1.0" encoding="utf-8"?>
<!-- This URDF was automatically created by SolidWorks to URDF Exporter! Originally created by Stephen Brawner (brawner@gmail.com) 
     Commit Version: 1.5.1-0-g916b5db  Build Version: 1.5.7152.31018
     For more information, please see http://wiki.ros.org/sw_urdf_exporter -->
<robot name="dw_descliption3">
  <material name="red">
    <color rgba="1.0 0.0 0.0 2.0"/>
  </material>
  <material name="gray">
    <color rgba="0.4 0.4 0.6 2.0"/>
  </material>
  <material name="light_gray">
    <color rgba="0.8 0.8 0.8 2.0"/>
  </material>

  <link name="dummy">
  </link>

  <joint name="dummy_joint" type="fixed">
     <parent link="dummy"/>
     <child link="base_link"/>
  </joint>

  <link name="base_link">
    <inertial>
      <origin xyz="3.183E-14 1.3076E-14 0.55565" rpy="0 0 0" />
      <mass value="1.5634" />
      <inertia ixx="0.007438" ixy="1.5146E-18" ixz="3.0063E-16" iyy="0.019355" iyz="6.1156E-17" izz="0.022991" />
    </inertial>
    <visual>
      <origin xyz="0 0 0" rpy="0 0 0" />
      <geometry>
        <mesh filename="package://dw_descliption3/meshes/base_link.STL" />
      </geometry>
      <material name="light_gray"/>
    </visual>
    <collision>
      <origin xyz="0 0 0" rpy="0 0 0" />
      <geometry>
        <mesh filename="package://dw_descliption3/meshes/base_link.STL" />
      </geometry>
    </collision>
  </link>

  <link name="A0_Link">
    <inertial>
      <origin xyz="-3.0966E-05 1.5445E-05 -0.027804" rpy="0 0 0" />
      <mass value="1.174" />
      <inertia ixx="0.00066725" ixy="-4.261E-09" ixz="9.7367E-09" iyy="0.00066813" iyz="-6.9091E-09" izz="0.0012253" />
    </inertial>
    <visual>
      <origin xyz="0 0 0" rpy="0 0 0" />
      <geometry>
        <mesh filename="package://dw_descliption3/meshes/A0_Link.STL" />
      </geometry>
      <material name="gray"/>
    </visual>
    <collision>
      <origin xyz="0 0 0" rpy="0 0 0" />
      <geometry>
        <mesh filename="package://dw_descliption3/meshes/A0_Link.STL" />
      </geometry>
    </collision>
  </link>


  <joint name="A0_joint" type="fixed">
    <origin xyz="0.3 -0.083 0.55565" rpy="-1.5708 0 -1.5708" />
    <parent link="base_link" />
    <child link="A0_Link" />
    <axis xyz="0 0 0" />
  </joint>


  <link name="A1_Link">
    <inertial>
      <origin xyz="-0.006102 -0.076629 0.007671" rpy="0 0 0" />
      <mass value="1.1557" />
      <inertia ixx="0.00080796" ixy="7.0307E-06" ixz="9.8387E-09" iyy="0.00089568" iyz="-6.5363E-09" izz="0.0013937" />
    </inertial>
    <visual>
      <origin xyz="0 0 0" rpy="0 0 0" />
      <geometry>
        <mesh filename="package://dw_descliption3/meshes/A1_Link.STL" />
      </geometry>
      <material name="gray"/>
    </visual>
    <collision>
      <origin xyz="0 0 0" rpy="0 0 0" />
      <geometry>
        <mesh filename="package://dw_descliption3/meshes/A1_Link.STL" />
      </geometry>
    </collision>
  </link>


  <joint name="A1_joint" type="revolute">
    <origin xyz="0 0 0" rpy="-1.5708 0.07854 -1.5708" />
    <parent link="A0_Link" />
    <child link="A1_Link" />
    <axis xyz="0.078459 0.99692 0" />
    <limit lower="-1.5075" upper="1.5075" effort="1000" velocity="1000" />
    <dynamics damping="10" friction="10" />
  </joint>


  <link name="A2_Link">
    <inertial>
      <origin xyz="-1.215E-05 -0.11553 0.14008" rpy="0 0 0" />
      <mass value="3.0792" />
      <inertia ixx="0.0033497" ixy="-3.3234E-08" ixz="-8.4729E-07" iyy="0.0027749" iyz="2.5095E-05" izz="0.0054304" />
    </inertial>
    <visual>
      <origin xyz="0 0 0" rpy="0 0 0" />
      <geometry>
        <mesh filename="package://dw_descliption3/meshes/A2_Link.STL" />
      </geometry>
      <material name="red"/>
    </visual>
    <collision>
      <origin xyz="0 0 0" rpy="0 0 0" />
      <geometry>
        <mesh filename="package://dw_descliption3/meshes/A2_Link.STL" />
      </geometry>
    </collision>
  </link>


  <joint name="A2_joint" type="revolute">
    <origin xyz="-0.0065513 -0.083243 0.0315" rpy="0 0 -2.4347" />
    <parent link="A1_Link" />
    <child link="A2_Link" />
    <axis xyz="0 0 1" />
    <limit lower="-1.5075" upper="1.5075" effort="1000" velocity="1000" />
    <dynamics damping="10" friction="10" />
  </joint>


  <link name="A3_Link">
    <inertial>
      <origin xyz="-3.0691E-08 -0.19011 0.10587" rpy="0 0 0" />
      <mass value="1.723" />
      <inertia ixx="0.0071994" ixy="-1.4133E-11" ixz="1.5336E-09" iyy="0.00075757" iyz="3.5455E-05" izz="0.0075465" />
    </inertial>
    <visual>
      <origin xyz="0 0 0" rpy="0 0 0" />
      <geometry>
        <mesh filename="package://dw_descliption3/meshes/A3_Link.STL" />
      </geometry>
      <material name="gray"/>
    </visual>
    <collision>
      <origin xyz="0 0 0" rpy="0 0 0" />
      <geometry>
        <mesh filename="package://dw_descliption3/meshes/A3_Link.STL" />
      </geometry>
    </collision>
  </link>


  <joint name="A3_joint" type="revolute">
    <origin xyz="0 -0.32 0.135" rpy="0 0 1.5708" />
    <parent link="A2_Link" />
    <child link="A3_Link" />
    <axis xyz="0 0 1" />
    <limit lower="-1.5075" upper="1.5075" effort="1000" velocity="1000" />
    <dynamics damping="10" friction="10" />
  </joint>


  <link name="B0_Link">
    <inertial>
      <origin xyz="-3.0966E-05 1.5445E-05 -0.027804" rpy="0 0 0" />
      <mass value="1.174" />
      <inertia ixx="0.00066725" ixy="-4.261E-09" ixz="9.7367E-09" iyy="0.00066813" iyz="-6.9091E-09" izz="0.0012253" />
    </inertial>
    <visual>
      <origin xyz="0 0 0" rpy="0 0 0" />
      <geometry>
        <mesh filename="package://dw_descliption3/meshes/B0_Link.STL" />
      </geometry>
      <material name="gray"/>
    </visual>
    <collision>
      <origin xyz="0 0 0" rpy="0 0 0" />
      <geometry>
        <mesh filename="package://dw_descliption3/meshes/B0_Link.STL" />
      </geometry>
    </collision>
  </link>


  <joint name="B0_joint" type="fixed">
    <origin xyz="0.3 0.083 0.55565" rpy="-1.5708 0 -1.5708" />
    <parent link="base_link" />
    <child link="B0_Link" />
    <axis xyz="0 0 0" />
  </joint>


  <link name="B1_Link">
    <inertial>
      <origin xyz="-0.006102 -0.076629 0.007671" rpy="0 0 0" />
      <mass value="1.1557" />
      <inertia ixx="0.00080796" ixy="7.0307E-06" ixz="9.8389E-09" iyy="0.00089568" iyz="-6.5362E-09" izz="0.0013937" />
    </inertial>
    <visual>
      <origin xyz="0 0 0" rpy="0 0 0" />
      <geometry>
        <mesh filename="package://dw_descliption3/meshes/B1_Link.STL" />
      </geometry>
      <material name="gray"/>
    </visual>
    <collision>
      <origin xyz="0 0 0" rpy="0 0 0" />
      <geometry>
        <mesh filename="package://dw_descliption3/meshes/B1_Link.STL" />
      </geometry>
    </collision>
  </link>


  <joint name="B1_joint" type="revolute">
    <origin xyz="0 0 0" rpy="-1.5708 0.07854 1.5708" />
    <parent link="B0_Link" />
    <child link="B1_Link" />
    <axis xyz="0.078459 0.99692 0" />
    <limit lower="-1.5075" upper="1.5075" effort="1000" velocity="1000" />
    <dynamics damping="10" friction="10" />
  </joint>


  <link name="B2_Link">
    <inertial>
      <origin xyz="-1.215E-05 -0.11553 0.14008" rpy="0 0 0" />
      <mass value="3.0792" />
      <inertia ixx="0.0033497" ixy="-3.3234E-08" ixz="-8.4729E-07" iyy="0.0027749" iyz="2.5095E-05" izz="0.0054304" />
    </inertial>
    <visual>
      <origin xyz="0 0 0" rpy="0 0 0" />
      <geometry>
        <mesh filename="package://dw_descliption3/meshes/B2_Link.STL" />
      </geometry>
      <material name="red"/>
    </visual>
    <collision>
      <origin xyz="0 0 0" rpy="0 0 0" />
      <geometry>
        <mesh filename="package://dw_descliption3/meshes/B2_Link.STL" />
      </geometry>
    </collision>
  </link>


  <joint name="B2_joint" type="revolute">
    <origin xyz="-0.0065513 -0.083243 0.0315" rpy="0 0 2.2777" />
    <parent link="B1_Link" />
    <child link="B2_Link" />
    <axis xyz="0 0 1" />
    <limit lower="-1.5075" upper="1.5075" effort="1000" velocity="1000" />
    <dynamics damping="10" friction="10" />
  </joint>


  <link name="B3_Link">
    <inertial>
      <origin xyz="-3.0691E-08 -0.19011 0.10587" rpy="0 0 0" />
      <mass value="1.723" />
      <inertia ixx="0.0071994" ixy="-1.4133E-11" ixz="1.5336E-09" iyy="0.00075757" iyz="3.5455E-05" izz="0.0075465" />
    </inertial>
    <visual>
      <origin xyz="0 0 0" rpy="0 0 0" />
      <geometry>
        <mesh filename="package://dw_descliption3/meshes/B3_Link.STL" />
      </geometry>
      <material name="gray"/>
    </visual>
    <collision>
      <origin xyz="0 0 0" rpy="0 0 0" />
      <geometry>
        <mesh filename="package://dw_descliption3/meshes/B3_Link.STL" />
      </geometry>
    </collision>
  </link>


  <joint name="B3_joint" type="revolute">
    <origin xyz="0 -0.32 0.135" rpy="0 0 -1.5708" />
    <parent link="B2_Link" />
    <child link="B3_Link" />
    <axis xyz="0 0 1" />
    <limit lower="-1.5075" upper="1.5075" effort="1000" velocity="1000" />
    <dynamics damping="10" friction="10" />
  </joint>


  <link name="C0_Link">
    <inertial>
      <origin xyz="-3.0966E-05 1.5445E-05 -0.027804" rpy="0 0 0" />
      <mass value="1.174" />
      <inertia ixx="0.00066725" ixy="-4.2609E-09" ixz="9.7367E-09" iyy="0.00066813" iyz="-6.9091E-09" izz="0.0012253" />
    </inertial>
    <visual>
      <origin xyz="0 0 0" rpy="0 0 0" />
      <geometry>
        <mesh filename="package://dw_descliption3/meshes/C0_Link.STL" />
      </geometry>
      <material name="gray"/>
    </visual>
    <collision>
      <origin xyz="0 0 0" rpy="0 0 0" />
      <geometry>
        <mesh filename="package://dw_descliption3/meshes/C0_Link.STL" />
      </geometry>
    </collision>
  </link>


  <joint name="C0_joint" type="fixed">
    <origin xyz="-0.3 -0.083 0.55565" rpy="1.5708 0 -1.5708" />
    <parent link="base_link" />
    <child link="C0_Link" />
    <axis xyz="0 0 0" />
  </joint>


  <link name="C1_Link">
    <inertial>
      <origin xyz="-0.006102 -0.076629 0.007671" rpy="0 0 0" />
      <mass value="1.1557" />
      <inertia ixx="0.00080796" ixy="7.0307E-06" ixz="9.8389E-09" iyy="0.00089568" iyz="-6.5363E-09" izz="0.0013937" />
    </inertial>
    <visual>
      <origin xyz="0 0 0" rpy="0 0 0" />
      <geometry>
        <mesh filename="package://dw_descliption3/meshes/C1_Link.STL" />
      </geometry>
      <material name="gray"/>
    </visual>
    <collision>
      <origin xyz="0 0 0" rpy="0 0 0" />
      <geometry>
        <mesh filename="package://dw_descliption3/meshes/C1_Link.STL" />
      </geometry>
    </collision>
  </link>


  <joint name="C1_joint" type="revolute">
    <origin xyz="0 0 0" rpy="-1.5708 0.07854 -1.5708" />
    <parent link="C0_Link" />
    <child link="C1_Link" />
    <axis xyz="0.078459 0.99692 0" />
    <limit lower="-1.5075" upper="1.5075" effort="1000" velocity="1000" />
    <dynamics damping="10" friction="10" />
  </joint>


  <link name="C2_Link">
    <inertial>
      <origin xyz="-1.215E-05 -0.11553 0.14008" rpy="0 0 0" />
      <mass value="3.0792" />
      <inertia ixx="0.0033497" ixy="-3.3234E-08" ixz="-8.4729E-07" iyy="0.0027749" iyz="2.5095E-05" izz="0.0054304" />
    </inertial>
    <visual>
      <origin xyz="0 0 0" rpy="0 0 0" />
      <geometry>
        <mesh filename="package://dw_descliption3/meshes/C2_Link.STL" />
      </geometry>
      <material name="red"/>
    </visual>
    <collision>
      <origin xyz="0 0 0" rpy="0 0 0" />
      <geometry>
        <mesh filename="package://dw_descliption3/meshes/C2_Link.STL" />
      </geometry>
    </collision>
  </link>


  <joint name="C2_joint" type="revolute">
    <origin xyz="-0.0065513 -0.083243 0.0315" rpy="0 0 0.70686" />
    <parent link="C1_Link" />
    <child link="C2_Link" />
    <axis xyz="0 0 1" />
    <limit lower="-1.5075" upper="1.5075" effort="1000" velocity="1000" />
    <dynamics damping="10" friction="10" />
  </joint>


  <link name="C3_Link">
    <inertial>
      <origin xyz="-3.0691E-08 -0.19011 0.10587" rpy="0 0 0" />
      <mass value="1.723" />
      <inertia ixx="0.0071994" ixy="-1.4133E-11" ixz="1.5336E-09" iyy="0.00075757" iyz="3.5455E-05" izz="0.0075465" />
    </inertial>
    <visual>
      <origin xyz="0 0 0" rpy="0 0 0" />
      <geometry>
        <mesh filename="package://dw_descliption3/meshes/C3_Link.STL" />
      </geometry>
      <material name="gray"/>
    </visual>
    <collision>
      <origin xyz="0 0 0" rpy="0 0 0" />
      <geometry>
        <mesh filename="package://dw_descliption3/meshes/C3_Link.STL" />
      </geometry>
    </collision>
  </link>


  <joint name="C3_joint" type="revolute">
    <origin xyz="0 -0.32 0.135" rpy="0 0 1.5708" />
    <parent link="C2_Link" />
    <child link="C3_Link" />
    <axis xyz="0 0 1" />
    <limit lower="-1.5075" upper="1.5075" effort="1000" velocity="1000" />
    <dynamics damping="10" friction="10" />
  </joint>


  <link name="D0_Link">
    <inertial>
      <origin xyz="-3.0966E-05 1.5445E-05 -0.027804" rpy="0 0 0" />
      <mass value="1.174" />
      <inertia ixx="0.00066725" ixy="-4.261E-09" ixz="9.7367E-09" iyy="0.00066813" iyz="-6.9091E-09" izz="0.0012253" />
    </inertial>
    <visual>
      <origin xyz="0 0 0" rpy="0 0 0" />
      <geometry>
        <mesh filename="package://dw_descliption3/meshes/D0_Link.STL" />
      </geometry>
      <material name="gray"/>
    </visual>
    <collision>
      <origin xyz="0 0 0" rpy="0 0 0" />
      <geometry>
        <mesh filename="package://dw_descliption3/meshes/D0_Link.STL" />
      </geometry>
    </collision>
  </link>


  <joint name="D0_joint" type="fixed">
    <origin xyz="-0.3 0.083 0.55565" rpy="1.5708 0 -1.5708" />
    <parent link="base_link" />
    <child link="D0_Link" />
    <axis xyz="0 0 0" />
  </joint>


  <link name="D1_Link">
    <inertial>
      <origin xyz="-0.006102 -0.076629 0.007671" rpy="0 0 0" />
      <mass value="1.1557" />
      <inertia ixx="0.00080796" ixy="7.0307E-06" ixz="9.8387E-09" iyy="0.00089568" iyz="-6.5363E-09" izz="0.0013937" />
    </inertial>
    <visual>
      <origin xyz="0 0 0" rpy="0 0 0" />
      <geometry>
        <mesh filename="package://dw_descliption3/meshes/D1_Link.STL" />
      </geometry>
      <material name="gray"/>
    </visual>
    <collision>
      <origin xyz="0 0 0" rpy="0 0 0" />
      <geometry>
        <mesh filename="package://dw_descliption3/meshes/D1_Link.STL" />
      </geometry>
    </collision>
  </link>


  <joint name="D1_joint" type="revolute">
    <origin xyz="0 0 0" rpy="-1.5708 0.07854 1.5708" />
    <parent link="D0_Link" />
    <child link="D1_Link" />
    <axis xyz="0.078459 0.99692 0" />
    <limit lower="-1.5075" upper="1.5075" effort="1000" velocity="1000" />
    <dynamics damping="10" friction="10" />
  </joint>


  <link name="D2_Link">
    <inertial>
      <origin xyz="-1.215E-05 -0.11553 0.14008" rpy="0 0 0" />
      <mass value="3.0792" />
      <inertia ixx="0.0033497" ixy="-3.3234E-08" ixz="-8.4729E-07" iyy="0.0027749" iyz="2.5095E-05" izz="0.0054304" />
    </inertial>
    <visual>
      <origin xyz="0 0 0" rpy="0 0 0" />
      <geometry>
        <mesh filename="package://dw_descliption3/meshes/D2_Link.STL" />
      </geometry>
      <material name="red"/>
    </visual>
    <collision>
      <origin xyz="0 0 0" rpy="0 0 0" />
      <geometry>
        <mesh filename="package://dw_descliption3/meshes/D2_Link.STL" />
      </geometry>
    </collision>
  </link>


  <joint name="D2_joint" type="revolute">
    <origin xyz="-0.0065513 -0.083243 0.0315" rpy="0 0 -0.86394" />
    <parent link="D1_Link" />
    <child link="D2_Link" />
    <axis xyz="0 0 1" />
    <limit lower="-1.5075" upper="1.5075" effort="1000" velocity="1000" />
    <dynamics damping="10" friction="10" />
  </joint>


  <link name="D3_Link">
    <inertial>
      <origin xyz="-3.0691E-08 -0.19011 0.10587" rpy="0 0 0" />
      <mass value="1.723" />
      <inertia ixx="0.0071994" ixy="-1.4133E-11" ixz="1.5338E-09" iyy="0.00075757" iyz="3.5455E-05" izz="0.0075465" />
    </inertial>
    <visual>
      <origin xyz="0 0 0" rpy="0 0 0" />
      <geometry>
        <mesh filename="package://dw_descliption3/meshes/D3_Link.STL" />
      </geometry>
      <material name="gray"/>
    </visual>
    <collision>
      <origin xyz="0 0 0" rpy="0 0 0" />
      <geometry>
        <mesh filename="package://dw_descliption3/meshes/D3_Link.STL" />
      </geometry>
    </collision>
  </link>


  <joint name="D3_joint" type="revolute">
    <origin xyz="0 -0.32 0.135" rpy="0 0 -1.5708" />
    <parent link="D2_Link" />
    <child link="D3_Link" />
    <axis xyz="0 0 1" />
    <limit lower="-1.5075" upper="1.5075" effort="1000" velocity="1000" />
    <dynamics damping="10" friction="10" />
  </joint>
</robot>
